<?xml version="1.0" ?>
<robot name="three_dof_planar_manipulator">
    <link name="world" />
    <joint name="world" type="fixed">
        <parent link="world" />
        <child link="base_link" />
        <origin xyz="0 0 0" rpy="0 0 0" />
        <axis xyz="0 0 0" />
    </joint>
    <link name="base_link">
        <visual>
            <origin xyz="0 0 0.002" rpy="0 0 0" />
            <geometry>
                <cylinder radius="0.06" length="0.005" />
            </geometry>
            <material name="white">
                <color rgba="1 1 1 1" />
            </material>
        </visual>
        <collision>
            <origin xyz="0 0 0.002" rpy="0 0 0" />
            <geometry>
                <cylinder radius="0.06" length="0.005" />
            </geometry>
        </collision>
        <inertial>
            <origin xyz="0 0 0.0025" rpy="0 0 0" />
            <mass value="0.1" />
            <inertia ixx="0.00054" ixy="0" ixz="0" iyy="0.00054" iyz="0" izz="0.00108" />
        </inertial>
    </link>
    <joint name="shoulder_joint" type="revolute">
        <parent link="base_link" />
        <child link="elbow_link" />
        <axis xyz="0 0 1" />
        <limit lower="0" upper="3.14" velocity="1.0" effort="1000.0" />
        <origin xyz="0.04 0 0.005" rpy="0 0 0" />
    </joint>
    <link name="elbow_link">
        <visual>
            <origin xyz="0.00 0.0 0.035" rpy="0.0 0.0 0.0" />
            <geometry>
                <box size="0.005 0.03 0.075" />
            </geometry>
            <material name="blue">
                <color rgba="0 0 0.8 1" />
            </material>
        </visual>
        <collision>
            <origin xyz="0.00 0.0 0.035" rpy="0.0 0.0 0.0" />
            <geometry>
                <box size="0.005 0.03 0.075" />
            </geometry>
        </collision>
        <inertial>
            <origin xyz="0.00 0.0 0.0375" rpy="0.0 0.0 0.0" />
            <mass value="0.15" />
            <inertia ixx="0.00015" ixy="0" ixz="0" iyy="0.00045" iyz="0" izz="0.0006" />
        </inertial>
    </link>
    <joint name="elbow_joint" type="revolute">
        <parent link="elbow_link" />
        <child link="arm_link" />
        <axis xyz="1 0 0" />
        <limit lower="0" upper="3.14" velocity="1.0" effort="1000.0" />
        <origin xyz="0.022 0 0.07" rpy="-1.59 0 0" />
    </joint>
    <link name="arm_link">
        <visual>
            <origin xyz="0.00 0 0.03" rpy="0.0 0.0 0" />
            <geometry>
                <box size="0.005 0.03 0.065" />
            </geometry>
            <material name="blue">
                <color rgba="0 0 0.8 1" />
            </material>
        </visual>
        <collision>
            <origin xyz="0.00 0 0.03" rpy="0.0 0.0 0" />
            <geometry>
                <box size="0.005 0.03 0.065" />
            </geometry>
        </collision>
        <inertial>
            <origin xyz="0.00 0 0.0325" rpy="0.0 0.0 0.0" />
            <mass value="0.12" />
            <inertia ixx="0.0001125" ixy="0" ixz="0" iyy="0.0003375" iyz="0" izz="0.00045" />
        </inertial>
    </link>
    <joint name="wrist_joint" type="revolute">
        <parent link="arm_link" />
        <child link="palm_link" />
        <axis xyz="1 0 0" />
        <limit lower="0.0" upper="3.14" velocity="1.0" effort="1000.0" />
        <origin xyz="-0.02 0 0.065" rpy="1.54 3.14 0" />
    </joint>
    <link name="palm_link">
        <visual>
            <origin xyz="0.00 0.01 0.042" rpy="0.0 0.0 0.0" />
            <geometry>
                <box size="0.02 0.005 0.095" />
            </geometry>
            <material name="blue">
                <color rgba="0 0 0.8 1" />
            </material>
        </visual>
        <collision>
            <origin xyz="0.00 0.01 0.042" rpy="0.0 0.0 0.0" />
            <geometry>
                <box size="0.02 0.005 0.095" />
            </geometry>
        </collision>
        <inertial>
            <origin xyz="0.00 0.01 0.0475" rpy="0.0 0.0 0.0" />
            <mass value="0.2" />
            <inertia ixx="0.000425" ixy="0" ixz="0" iyy="0.0000525" iyz="0" izz="0.000475" />
        </inertial>
    </link>
    <transmission name="trans_shoulder_joint">
        <type>transmission_interface/SimpleTransmission</type>
        <joint name="shoulder_joint">
            <hardwareInterface>hardware_interface/EffortJointInterface</hardwareInterface>
        </joint>
        <actuator name="shoulder_joint_motor">
            <hardwareInterface>hardware_interface/EffortJointInterface</hardwareInterface>
            <mechanicalReduction>1</mechanicalReduction>
        </actuator>
    </transmission>
    <transmission name="trans_elbow_joint">
        <type>transmission_interface/SimpleTransmission</type>
        <joint name="elbow_joint">
            <hardwareInterface>hardware_interface/EffortJointInterface</hardwareInterface>
        </joint>
        <actuator name="elbow_joint_motor">
            <hardwareInterface>hardware_interface/EffortJointInterface</hardwareInterface>
            <mechanicalReduction>1</mechanicalReduction>
        </actuator>
    </transmission>
    <transmission name="trans_wrist_joint">
        <type>transmission_interface/SimpleTransmission</type>
        <joint name="wrist_joint">
            <hardwareInterface>hardware_interface/EffortJointInterface</hardwareInterface>
        </joint>
        <actuator name="wrist_joint_motor">
            <hardwareInterface>hardware_interface/EffortJointInterface</hardwareInterface>
            <mechanicalReduction>1</mechanicalReduction>
        </actuator>
    </transmission>
    <gazebo>
        <plugin name="gazebo_ros_control">
            <robotNamespace>/</robotNamespace>
        </plugin>
    </gazebo>
</robot>

